[0m09:22:11.400537 [debug] [MainThread]: Sending event: {'category': 'dbt', 'action': 'invocation', 'label': 'start', 'context': [<snowplow_tracker.self_describing_json.SelfDescribingJson object at 0x000001E9D10685D0>, <snowplow_tracker.self_describing_json.SelfDescribingJson object at 0x000001E9D1067A10>, <snowplow_tracker.self_describing_json.SelfDescribingJson object at 0x000001E9D1067850>]}


============================== 09:22:11.418504 | fa3a26b4-89e4-4023-9dc2-48647af8660a ==============================
[0m09:22:11.418504 [info ] [MainThread]: Running with dbt=1.9.0
[0m09:22:11.418504 [debug] [MainThread]: running dbt with arguments {'printer_width': '80', 'indirect_selection': 'eager', 'write_json': 'True', 'log_cache_events': 'False', 'partial_parse': 'True', 'cache_selected_only': 'False', 'warn_error': 'None', 'fail_fast': 'False', 'profiles_dir': 'C:\\Users\\habdullayev\\.dbt', 'log_path': 'logs', 'debug': 'False', 'version_check': 'True', 'use_colors': 'True', 'use_experimental_parser': 'False', 'empty': 'None', 'quiet': 'False', 'no_print': 'None', 'warn_error_options': 'WarnErrorOptions(include=[], exclude=[])', 'introspect': 'True', 'log_format': 'default', 'static_parser': 'True', 'target_path': 'None', 'invocation_command': 'dbt ', 'send_anonymous_usage_stats': 'True'}
[0m09:22:11.422510 [error] [MainThread]: Encountered an error:
Runtime Error
  No dbt_project.yml found at expected path c:\Users\habdullayev\Documents\others\GitHub\My Projects\Data-Engineering_Bootcamp\06.dbt\dbtLearn\dbt_packages\dbt-utils-1.3.0\integration_tests\dbt_packages\dbt_utils\dbt_project.yml
  Verify that each entry within packages.yml (and their transitive dependencies) contains a file named dbt_project.yml
  
[0m09:22:11.423506 [debug] [MainThread]: Command `cli deps` failed at 09:22:11.423506 after 0.20 seconds
[0m09:22:11.424498 [debug] [MainThread]: Sending event: {'category': 'dbt', 'action': 'invocation', 'label': 'end', 'context': [<snowplow_tracker.self_describing_json.SelfDescribingJson object at 0x000001E9D1019250>, <snowplow_tracker.self_describing_json.SelfDescribingJson object at 0x000001E9D106BB10>, <snowplow_tracker.self_describing_json.SelfDescribingJson object at 0x000001E9CA9908D0>]}
[0m09:22:11.424498 [debug] [MainThread]: Flushing usage events
[0m09:22:11.940633 [debug] [MainThread]: Sending event: {'category': 'dbt', 'action': 'invocation', 'label': 'start', 'context': [<snowplow_tracker.self_describing_json.SelfDescribingJson object at 0x00000234D3E48DD0>, <snowplow_tracker.self_describing_json.SelfDescribingJson object at 0x00000234D6E38590>, <snowplow_tracker.self_describing_json.SelfDescribingJson object at 0x00000234D6E38610>]}


============================== 09:22:11.949680 | 1a6b0cbb-53ab-4717-aa72-10e1709edb0d ==============================
[0m09:22:11.949680 [info ] [MainThread]: Running with dbt=1.9.0
[0m09:22:11.949680 [debug] [MainThread]: running dbt with arguments {'printer_width': '80', 'indirect_selection': 'eager', 'log_cache_events': 'False', 'write_json': 'True', 'partial_parse': 'True', 'cache_selected_only': 'False', 'warn_error': 'None', 'version_check': 'True', 'profiles_dir': 'C:\\Users\\habdullayev\\.dbt', 'log_path': 'logs', 'fail_fast': 'False', 'debug': 'False', 'use_colors': 'True', 'use_experimental_parser': 'False', 'empty': 'None', 'quiet': 'False', 'no_print': 'None', 'warn_error_options': 'WarnErrorOptions(include=[], exclude=[])', 'static_parser': 'True', 'invocation_command': 'dbt ', 'log_format': 'default', 'target_path': 'None', 'introspect': 'True', 'send_anonymous_usage_stats': 'True'}
[0m09:22:11.950714 [error] [MainThread]: Encountered an error:
Runtime Error
  No dbt_project.yml found at expected path c:\Users\habdullayev\Documents\others\GitHub\My Projects\Data-Engineering_Bootcamp\06.dbt\dbtLearn\dbt_packages\dbt-utils-1.3.0\integration_tests\dbt_packages\dbt_utils\dbt_project.yml
  Verify that each entry within packages.yml (and their transitive dependencies) contains a file named dbt_project.yml
  
[0m09:22:11.952098 [debug] [MainThread]: Command `cli deps` failed at 09:22:11.952098 after 0.23 seconds
[0m09:22:11.953107 [debug] [MainThread]: Sending event: {'category': 'dbt', 'action': 'invocation', 'label': 'end', 'context': [<snowplow_tracker.self_describing_json.SelfDescribingJson object at 0x00000234D6DE9310>, <snowplow_tracker.self_describing_json.SelfDescribingJson object at 0x00000234D6E5B110>, <snowplow_tracker.self_describing_json.SelfDescribingJson object at 0x00000234D6E58890>]}
[0m09:22:11.953107 [debug] [MainThread]: Flushing usage events
[0m09:22:11.956104 [debug] [MainThread]: An error was encountered while trying to flush usage events
[0m09:22:12.403749 [debug] [MainThread]: An error was encountered while trying to flush usage events
[0m09:22:12.599575 [debug] [MainThread]: Sending event: {'category': 'dbt', 'action': 'invocation', 'label': 'start', 'context': [<snowplow_tracker.self_describing_json.SelfDescribingJson object at 0x00000204D9F981D0>, <snowplow_tracker.self_describing_json.SelfDescribingJson object at 0x00000204D9F787D0>, <snowplow_tracker.self_describing_json.SelfDescribingJson object at 0x00000204D6F5CB50>]}


============================== 09:22:12.609614 | 0981f001-5af4-4cb1-a5f8-a90eb32b7efe ==============================
[0m09:22:12.609614 [info ] [MainThread]: Running with dbt=1.9.0
[0m09:22:12.611125 [debug] [MainThread]: running dbt with arguments {'printer_width': '80', 'indirect_selection': 'eager', 'write_json': 'True', 'log_cache_events': 'False', 'partial_parse': 'True', 'cache_selected_only': 'False', 'warn_error': 'None', 'debug': 'False', 'fail_fast': 'False', 'log_path': 'logs', 'profiles_dir': 'C:\\Users\\habdullayev\\.dbt', 'version_check': 'True', 'use_colors': 'True', 'use_experimental_parser': 'False', 'empty': 'None', 'quiet': 'False', 'no_print': 'None', 'log_format': 'default', 'static_parser': 'True', 'warn_error_options': 'WarnErrorOptions(include=[], exclude=[])', 'invocation_command': 'dbt ', 'target_path': 'None', 'introspect': 'True', 'send_anonymous_usage_stats': 'True'}
[0m09:22:12.613672 [error] [MainThread]: Encountered an error:
Runtime Error
  No dbt_project.yml found at expected path c:\Users\habdullayev\Documents\others\GitHub\My Projects\Data-Engineering_Bootcamp\06.dbt\dbtLearn\dbt_packages\dbt-utils-1.3.0\integration_tests\dbt_packages\dbt_utils\integration_tests\dbt_packages\dbt_utils\dbt_project.yml
  Verify that each entry within packages.yml (and their transitive dependencies) contains a file named dbt_project.yml
  
[0m09:22:12.616212 [debug] [MainThread]: Command `cli deps` failed at 09:22:12.616212 after 0.23 seconds
[0m09:22:12.617223 [debug] [MainThread]: Sending event: {'category': 'dbt', 'action': 'invocation', 'label': 'end', 'context': [<snowplow_tracker.self_describing_json.SelfDescribingJson object at 0x00000204D9F981D0>, <snowplow_tracker.self_describing_json.SelfDescribingJson object at 0x00000204D9F2D390>, <snowplow_tracker.self_describing_json.SelfDescribingJson object at 0x00000204D38808D0>]}
[0m09:22:12.618732 [debug] [MainThread]: Flushing usage events
[0m09:22:12.759193 [debug] [MainThread]: Sending event: {'category': 'dbt', 'action': 'invocation', 'label': 'start', 'context': [<snowplow_tracker.self_describing_json.SelfDescribingJson object at 0x0000024C53789950>, <snowplow_tracker.self_describing_json.SelfDescribingJson object at 0x0000024C5378BF50>, <snowplow_tracker.self_describing_json.SelfDescribingJson object at 0x0000024C537A8550>]}


============================== 09:22:12.769280 | 7e681caf-3d0e-4228-994f-de3e2e09c54f ==============================
[0m09:22:12.769280 [info ] [MainThread]: Running with dbt=1.9.0
[0m09:22:12.769280 [debug] [MainThread]: running dbt with arguments {'printer_width': '80', 'indirect_selection': 'eager', 'log_cache_events': 'False', 'write_json': 'True', 'partial_parse': 'True', 'cache_selected_only': 'False', 'profiles_dir': 'C:\\Users\\habdullayev\\.dbt', 'debug': 'False', 'version_check': 'True', 'log_path': 'logs', 'fail_fast': 'False', 'warn_error': 'None', 'use_colors': 'True', 'use_experimental_parser': 'False', 'no_print': 'None', 'quiet': 'False', 'empty': 'None', 'log_format': 'default', 'static_parser': 'True', 'warn_error_options': 'WarnErrorOptions(include=[], exclude=[])', 'introspect': 'True', 'target_path': 'None', 'invocation_command': 'dbt ', 'send_anonymous_usage_stats': 'True'}
[0m09:22:12.771276 [error] [MainThread]: Encountered an error:
Runtime Error
  No dbt_project.yml found at expected path c:\Users\habdullayev\Documents\others\GitHub\My Projects\Data-Engineering_Bootcamp\06.dbt\dbtLearn\dbt_packages\dbt-utils-1.3.0\integration_tests\dbt_packages\dbt_utils\integration_tests\dbt_packages\dbt_utils\dbt_project.yml
  Verify that each entry within packages.yml (and their transitive dependencies) contains a file named dbt_project.yml
  
[0m09:22:12.772280 [debug] [MainThread]: Command `cli deps` failed at 09:22:12.772280 after 0.18 seconds
[0m09:22:12.773283 [debug] [MainThread]: Sending event: {'category': 'dbt', 'action': 'invocation', 'label': 'end', 'context': [<snowplow_tracker.self_describing_json.SelfDescribingJson object at 0x0000024C5373D4D0>, <snowplow_tracker.self_describing_json.SelfDescribingJson object at 0x0000024C537A9610>, <snowplow_tracker.self_describing_json.SelfDescribingJson object at 0x0000024C537A8110>]}
[0m09:22:12.774276 [debug] [MainThread]: Flushing usage events
[0m09:22:12.777797 [debug] [MainThread]: Sending event: {'category': 'dbt', 'action': 'invocation', 'label': 'start', 'context': [<snowplow_tracker.self_describing_json.SelfDescribingJson object at 0x000001FADC3181D0>, <snowplow_tracker.self_describing_json.SelfDescribingJson object at 0x000001FADC2FA850>, <snowplow_tracker.self_describing_json.SelfDescribingJson object at 0x000001FADC318610>]}


============================== 09:22:12.784322 | 29e822d3-a2e0-4c84-8f6b-5cccad1c9120 ==============================
[0m09:22:12.784322 [info ] [MainThread]: Running with dbt=1.9.0
[0m09:22:12.785833 [debug] [MainThread]: running dbt with arguments {'printer_width': '80', 'indirect_selection': 'eager', 'write_json': 'True', 'log_cache_events': 'False', 'partial_parse': 'True', 'cache_selected_only': 'False', 'profiles_dir': 'C:\\Users\\habdullayev\\.dbt', 'fail_fast': 'False', 'version_check': 'True', 'log_path': 'logs', 'warn_error': 'None', 'debug': 'False', 'use_colors': 'True', 'use_experimental_parser': 'False', 'no_print': 'None', 'quiet': 'False', 'empty': 'None', 'log_format': 'default', 'static_parser': 'True', 'warn_error_options': 'WarnErrorOptions(include=[], exclude=[])', 'introspect': 'True', 'target_path': 'None', 'invocation_command': 'dbt ', 'send_anonymous_usage_stats': 'True'}
[0m09:22:12.786844 [error] [MainThread]: Encountered an error:
Runtime Error
  No dbt_project.yml found at expected path c:\Users\habdullayev\Documents\others\GitHub\My Projects\Data-Engineering_Bootcamp\06.dbt\dbtLearn\dbt_packages\dbt-utils-1.3.0\integration_tests\dbt_packages\dbt_utils\integration_tests\dbt_project.yml
  Verify that each entry within packages.yml (and their transitive dependencies) contains a file named dbt_project.yml
  
[0m09:22:12.787845 [debug] [MainThread]: Command `cli deps` failed at 09:22:12.787845 after 0.17 seconds
[0m09:22:12.789355 [debug] [MainThread]: Sending event: {'category': 'dbt', 'action': 'invocation', 'label': 'end', 'context': [<snowplow_tracker.self_describing_json.SelfDescribingJson object at 0x000001FADC2A9350>, <snowplow_tracker.self_describing_json.SelfDescribingJson object at 0x000001FAD5C00950>, <snowplow_tracker.self_describing_json.SelfDescribingJson object at 0x000001FADC2F8490>]}
[0m09:22:12.790369 [debug] [MainThread]: Flushing usage events
[0m09:22:13.081097 [debug] [MainThread]: An error was encountered while trying to flush usage events
[0m09:22:13.222505 [debug] [MainThread]: An error was encountered while trying to flush usage events
[0m09:22:13.236050 [debug] [MainThread]: An error was encountered while trying to flush usage events
[0m09:22:13.862696 [debug] [MainThread]: Sending event: {'category': 'dbt', 'action': 'invocation', 'label': 'start', 'context': [<snowplow_tracker.self_describing_json.SelfDescribingJson object at 0x000001BA9F139CD0>, <snowplow_tracker.self_describing_json.SelfDescribingJson object at 0x000001BAA214A510>, <snowplow_tracker.self_describing_json.SelfDescribingJson object at 0x000001BAA2149190>]}


============================== 09:22:13.875212 | 9e7650d0-477f-440a-ad02-50531abf5f86 ==============================
[0m09:22:13.875212 [info ] [MainThread]: Running with dbt=1.9.0
[0m09:22:13.876212 [debug] [MainThread]: running dbt with arguments {'printer_width': '80', 'indirect_selection': 'eager', 'log_cache_events': 'False', 'write_json': 'True', 'partial_parse': 'True', 'cache_selected_only': 'False', 'profiles_dir': 'C:\\Users\\habdullayev\\.dbt', 'fail_fast': 'False', 'debug': 'False', 'log_path': 'logs', 'version_check': 'True', 'warn_error': 'None', 'use_colors': 'True', 'use_experimental_parser': 'False', 'empty': 'None', 'quiet': 'False', 'no_print': 'None', 'log_format': 'default', 'invocation_command': 'dbt ', 'introspect': 'True', 'static_parser': 'True', 'target_path': 'None', 'warn_error_options': 'WarnErrorOptions(include=[], exclude=[])', 'send_anonymous_usage_stats': 'True'}
[0m09:22:13.878307 [error] [MainThread]: Encountered an error:
Runtime Error
  No dbt_project.yml found at expected path c:\Users\habdullayev\Documents\others\GitHub\My Projects\Data-Engineering_Bootcamp\06.dbt\dbtLearn\dbt_packages\dbt-utils-1.3.0\integration_tests\dbt_packages\dbt_utils\integration_tests\dbt_project.yml
  Verify that each entry within packages.yml (and their transitive dependencies) contains a file named dbt_project.yml
  
[0m09:22:13.880748 [debug] [MainThread]: Command `cli deps` failed at 09:22:13.880748 after 0.26 seconds
[0m09:22:13.881747 [debug] [MainThread]: Sending event: {'category': 'dbt', 'action': 'invocation', 'label': 'end', 'context': [<snowplow_tracker.self_describing_json.SelfDescribingJson object at 0x000001BAA20F9350>, <snowplow_tracker.self_describing_json.SelfDescribingJson object at 0x000001BA9BA90950>, <snowplow_tracker.self_describing_json.SelfDescribingJson object at 0x000001BAA2148290>]}
[0m09:22:13.882959 [debug] [MainThread]: Flushing usage events
[0m09:22:14.325493 [debug] [MainThread]: An error was encountered while trying to flush usage events
[0m10:53:59.930657 [debug] [MainThread]: Sending event: {'category': 'dbt', 'action': 'invocation', 'label': 'start', 'context': [<snowplow_tracker.self_describing_json.SelfDescribingJson object at 0x7f14a121eff0>, <snowplow_tracker.self_describing_json.SelfDescribingJson object at 0x7f14a2d867e0>, <snowplow_tracker.self_describing_json.SelfDescribingJson object at 0x7f14a10fdf70>]}


============================== 10:53:59.948124 | 55c4d349-1220-4cf4-93ef-86411ebec6b8 ==============================
[0m10:53:59.948124 [info ] [MainThread]: Running with dbt=1.9.3
[0m10:53:59.948914 [debug] [MainThread]: running dbt with arguments {'printer_width': '80', 'indirect_selection': 'eager', 'write_json': 'True', 'log_cache_events': 'False', 'partial_parse': 'True', 'cache_selected_only': 'False', 'profiles_dir': '/root/.dbt', 'version_check': 'True', 'debug': 'False', 'log_path': 'logs', 'warn_error': 'None', 'fail_fast': 'False', 'use_colors': 'True', 'use_experimental_parser': 'False', 'no_print': 'None', 'quiet': 'False', 'empty': 'False', 'warn_error_options': 'WarnErrorOptions(include=[], exclude=[])', 'introspect': 'True', 'static_parser': 'True', 'log_format': 'default', 'target_path': 'None', 'invocation_command': 'dbt run', 'send_anonymous_usage_stats': 'True'}
[0m10:53:59.949559 [error] [MainThread]: Encountered an error:
Runtime Error
  No dbt_project.yml found at expected path /mnt/c/Users/habdullayev/Documents/others/GitHub/My Projects/Data-Engineering_Bootcamp/dbt_project.yml
  Verify that each entry within packages.yml (and their transitive dependencies) contains a file named dbt_project.yml
  
[0m10:53:59.951914 [debug] [MainThread]: Resource report: {"command_name": "run", "command_success": false, "command_wall_clock_time": 0.06663415, "process_in_blocks": "7072", "process_kernel_time": 0.507083, "process_mem_max_rss": "91068", "process_out_blocks": "0", "process_user_time": 1.256684}
[0m10:53:59.952526 [debug] [MainThread]: Command `dbt run` failed at 10:53:59.952446 after 0.07 seconds
[0m10:53:59.952995 [debug] [MainThread]: Sending event: {'category': 'dbt', 'action': 'invocation', 'label': 'end', 'context': [<snowplow_tracker.self_describing_json.SelfDescribingJson object at 0x7f14a0e88ef0>, <snowplow_tracker.self_describing_json.SelfDescribingJson object at 0x7f14a1097fb0>, <snowplow_tracker.self_describing_json.SelfDescribingJson object at 0x7f14a1020b30>]}
[0m10:53:59.953412 [debug] [MainThread]: Flushing usage events
[0m10:54:00.498628 [debug] [MainThread]: An error was encountered while trying to flush usage events
